Workbook

Sheet Influence Matrix
B1: {=TRANSPOSE(A2:A43)} -> Addiction | C1: Agriculture | D1: Authoritarianism | E1: Birthrate | F1: Corruption | G1: Cost of Living | H1: Crime | I1: Deathrate | J1: Discrimination | K1: Diversity | L1: Edu: Access | M1: Edu: Cost | N1: Edu: Quality | O1: Employment | P1: Energy Production | Q1: Equality | R1: Family Values | S1: Freedom of Speech | T1: Gun Rights | U1: HC Access | V1: HC Cost | W1: HC Quality | X1: Homelessness | Y1: Immigration | Z1: Infrastructure | AA1: Innovation | AB1: Law Enforcement | AC1: Liberty | AD1: Market Freedom | AE1: Mental Health | AF1: Military | AG1: Minimum Wage | AH1: Pollution | AI1: Poverty | AJ1: Public Trust | AK1: Purpose/Meaning | AL1: Religion | AM1: Sickness/Disease | AN1: Taxes | AO1: Tech | AP1: Transportation | AQ1: Welfare Support
A2: =Sliders!A1 -> Addiction | B2: 1 | C2: 0.05 | D2: 0.08 | E2: 0 | F2: 0 | G2: 0 | H2: 0.21 | I2: 0 | J2: 0.15 | K2: 0 | L2: -0.12 | M2: 0.1 | N2: -0.14 | O2: -0.17 | P2: 0 | Q2: 0 | R2: 0 | S2: 0 | T2: 0 | U2: 0 | V2: 0 | W2: 0 | X2: 0 | Y2: 0 | Z2: 0 | AA2: 0 | AB2: 0 | AC2: 0 | AD2: 0 | AE2: 0 | AF2: 0 | AG2: 0 | AH2: 0 | AI2: 0 | AJ2: 0 | AK2: 0 | AL2: 0 | AM2: 0 | AN2: 0 | AO2: 0 | AP2: 0 | AQ2: 0
A3: =Sliders!A2 -> Agriculture | B3: -0.08 | C3: 1 | D3: -0.15 | E3: 0.05 | F3: -0.1 | G3: 0 | H3: -0.16 | I3: 0 | J3: -0.21 | K3: 0 | L3: 0.16 | M3: 0 | N3: 0.23 | O3: 0.14 | P3: 0.33 | Q3: 0.1 | R3: 0 | S3: 0 | T3: 0 | U3: 0 | V3: 0 | W3: 0 | X3: 0 | Y3: 0 | Z3: 0 | AA3: 0 | AB3: 0 | AC3: 0 | AD3: 0 | AE3: 0 | AF3: 0 | AG3: 0 | AH3: 0 | AI3: 0 | AJ3: 0 | AK3: 0 | AL3: 0 | AM3: 0 | AN3: 0 | AO3: 0 | AP3: 0 | AQ3: 0
A4: =Sliders!A3 -> Authoritarianism | B4: 0 | C4: 0.14 | D4: 1 | E4: 0 | F4: 0.16 | G4: 0 | H4: 0.11 | I4: 0 | J4: 0.02 | K4: 0 | L4: -0.11 | M4: 0 | N4: -0.18 | O4: 0 | P4: 0.03 | Q4: 0 | R4: 0 | S4: 0 | T4: 0 | U4: 0 | V4: 0 | W4: 0 | X4: 0 | Y4: 0 | Z4: 0 | AA4: 0 | AB4: 0 | AC4: 0 | AD4: 0 | AE4: 0 | AF4: 0 | AG4: 0 | AH4: 0 | AI4: 0 | AJ4: 0 | AK4: 0 | AL4: 0 | AM4: 0 | AN4: 0 | AO4: 0 | AP4: 0 | AQ4: 0
A5: =Sliders!A4 -> Birthrate | B5: -0.16 | C5: 0.13 | D5: 0 | E5: 1 | F5: 0 | G5: -0.13 | H5: -0.15 | I5: 0 | J5: -0.12 | K5: 0 | L5: -0.1 | M5: 0 | N5: -0.15 | O5: 0.18 | P5: 0 | Q5: 0.05 | R5: 0 | S5: 0 | T5: 0 | U5: 0 | V5: 0 | W5: 0 | X5: 0 | Y5: 0 | Z5: 0 | AA5: 0 | AB5: 0 | AC5: 0 | AD5: 0 | AE5: 0 | AF5: 0 | AG5: 0 | AH5: 0 | AI5: 0 | AJ5: 0 | AK5: 0 | AL5: 0 | AM5: 0 | AN5: 0 | AO5: 0 | AP5: 0 | AQ5: 0
A6: =Sliders!A5 -> Corruption | B6: 0 | C6: 0 | D6: 0.3 | E6: 0 | F6: 1 | G6: 0 | H6: 0.33 | I6: 0 | J6: 0.1 | K6: 0 | L6: -0.09 | M6: 0 | N6: -0.13 | O6: 0 | P6: 0.05 | Q6: -0.23 | R6: 0 | S6: 0 | T6: 0 | U6: 0 | V6: 0 | W6: 0 | X6: 0 | Y6: 0 | Z6: 0 | AA6: 0 | AB6: 0 | AC6: 0 | AD6: 0 | AE6: 0 | AF6: 0 | AG6: 0 | AH6: 0 | AI6: 0 | AJ6: 0 | AK6: 0 | AL6: 0 | AM6: 0 | AN6: 0 | AO6: 0 | AP6: 0 | AQ6: 0
A7: =Sliders!A6 -> Cost of Living | B7: 0.19 | C7: -0.16 | D7: 0 | E7: 0.04 | F7: 0.18 | G7: 1 | H7: 0.12 | I7: 0 | J7: 0 | K7: 0 | L7: 0 | M7: 0.02 | N7: 0.15 | O7: 0.06 | P7: 0.04 | Q7: 0 | R7: 0 | S7: 0 | T7: 0 | U7: 0 | V7: 0 | W7: 0 | X7: 0 | Y7: 0 | Z7: 0 | AA7: 0 | AB7: 0 | AC7: 0 | AD7: 0 | AE7: 0 | AF7: 0 | AG7: 0 | AH7: 0 | AI7: 0 | AJ7: 0 | AK7: 0 | AL7: 0 | AM7: 0 | AN7: 0 | AO7: 0 | AP7: 0 | AQ7: 0
A8: =Sliders!A7 -> Crime | B8: 0.3 | C8: -0.13 | D8: -0.07 | E8: 0 | F8: 0.24 | G8: 0.02 | H8: 1 | I8: 0 | J8: 0.12 | K8: 0.05 | L8: -0.23 | M8: 0 | N8: -0.17 | O8: -0.18 | P8: 0.2 | Q8: -0.17 | R8: 0 | S8: 0 | T8: 0 | U8: 0 | V8: 0 | W8: 0 | X8: 0 | Y8: 0 | Z8: 0 | AA8: 0 | AB8: 0 | AC8: 0 | AD8: 0 | AE8: 0 | AF8: 0 | AG8: 0 | AH8: 0 | AI8: 0 | AJ8: 0 | AK8: 0 | AL8: 0 | AM8: 0 | AN8: 0 | AO8: 0 | AP8: 0 | AQ8: 0
A9: =Sliders!A8 -> Deathrate | B9: 0.31 | C9: 0.14 | D9: -0.13 | E9: -0.02 | F9: 0.21 | G9: 0 | H9: 0.36 | I9: 1 | J9: 0.1 | K9: 0 | L9: -0.13 | M9: 0 | N9: -0.21 | O9: -0.13 | P9: -0.12 | Q9: -0.12 | R9: 0 | S9: 0 | T9: 0 | U9: 0 | V9: 0 | W9: 0 | X9: 0 | Y9: 0 | Z9: 0 | AA9: 0 | AB9: 0 | AC9: 0 | AD9: 0 | AE9: 0 | AF9: 0 | AG9: 0 | AH9: 0 | AI9: 0 | AJ9: 0 | AK9: 0 | AL9: 0 | AM9: 0 | AN9: 0 | AO9: 0 | AP9: 0 | AQ9: 0
A10: =Sliders!A9 -> Discrimination | B10: 0 | C10: 0.12 | D10: 0.27 | E10: 0 | F10: 0.25 | G10: 0 | H10: 0 | I10: 0 | J10: 1 | K10: 0.1 | L10: -0.16 | M10: 0 | N10: 0 | O10: 0 | P10: 0 | Q10: 0 | R10: 0 | S10: 0 | T10: 0 | U10: 0 | V10: 0 | W10: 0 | X10: 0 | Y10: 0 | Z10: 0 | AA10: 0 | AB10: 0 | AC10: 0 | AD10: 0 | AE10: 0 | AF10: 0 | AG10: 0 | AH10: 0 | AI10: 0 | AJ10: 0 | AK10: 0 | AL10: 0 | AM10: 0 | AN10: 0 | AO10: 0 | AP10: 0 | AQ10: 0
A11: =Sliders!A10 -> Diversity | B11: 0 | C11: 0.11 | D11: -0.2 | E11: 0 | F11: 0 | G11: 0 | H11: 0 | I11: 0 | J11: -0.17 | K11: 1 | L11: 0.1 | M11: -0.04 | N11: 0.03 | O11: 0 | P11: 0 | Q11: 0 | R11: 0 | S11: 0 | T11: 0 | U11: 0 | V11: 0 | W11: 0 | X11: 0 | Y11: 0 | Z11: 0 | AA11: 0 | AB11: 0 | AC11: 0 | AD11: 0 | AE11: 0 | AF11: 0 | AG11: 0 | AH11: 0 | AI11: 0 | AJ11: 0 | AK11: 0 | AL11: 0 | AM11: 0 | AN11: 0 | AO11: 0 | AP11: 0 | AQ11: 0
A12: =Sliders!A11 -> Edu: Access | B12: -0.07 | C12: 0.09 | D12: 0 | E12: -0.03 | F12: -0.15 | G12: 0 | H12: 0 | I12: 0 | J12: -0.2 | K12: 0 | L12: 1 | M12: 0 | N12: 0 | O12: 0.04 | P12: 0.25 | Q12: 0 | R12: 0 | S12: 0 | T12: 0 | U12: 0 | V12: 0 | W12: 0 | X12: 0 | Y12: 0 | Z12: 0 | AA12: 0 | AB12: 0 | AC12: 0 | AD12: 0 | AE12: 0 | AF12: 0 | AG12: 0 | AH12: 0 | AI12: 0 | AJ12: 0 | AK12: 0 | AL12: 0 | AM12: 0 | AN12: 0 | AO12: 0 | AP12: 0 | AQ12: 0
A13: =Sliders!A12 -> Edu: Cost | B13: 0 | C13: -0.08 | D13: 0 | E13: 0.09 | F13: 0.12 | G13: 0.05 | H13: 0.02 | I13: 0 | J13: 0.09 | K13: 0 | L13: 0 | M13: 1 | N13: 0 | O13: -0.02 | P13: 0 | Q13: 0 | R13: 0 | S13: 0 | T13: 0 | U13: 0 | V13: 0 | W13: 0 | X13: 0 | Y13: 0 | Z13: 0 | AA13: 0 | AB13: 0 | AC13: 0 | AD13: 0 | AE13: 0 | AF13: 0 | AG13: 0 | AH13: 0 | AI13: 0 | AJ13: 0 | AK13: 0 | AL13: 0 | AM13: 0 | AN13: 0 | AO13: 0 | AP13: 0 | AQ13: 0
... A43: =Sliders!A42 -> Welfare Support | B43: 0.22 | C43: 0.18 | D43: 0.14 | E43: 0.03 | F43: -0.16 | G43: 0.3 | H43: 0 | I43: 0 | J43: -0.17 | K43: -0.06 | L43: 0.16 | M43: 0 | N43: 0.05 | O43: -0.06 | P43: 0.06 | Q43: 0 | R43: 0 | S43: 0 | T43: 0 | U43: 0 | V43: 0 | W43: 0 | X43: 0 | Y43: 0 | Z43: 0 | AA43: 0 | AB43: 0 | AC43: 0 | AD43: 0 | AE43: 0 | AF43: 0 | AG43: 0 | AH43: 0 | AI43: 0 | AJ43: 0 | AK43: 0 | AL43: 0 | AM43: 0 | AN43: 0 | AO43: 0 | AP43: 0 | AQ43: 1

Sheet Sources
A1: src_key | B1: From | C1: To | D1: Weight | E1: Shape | F1: Shape_params | G1: Sign conf | H1: Mag conf | I1: Status | J1: Notes
A2: Addiction_Agriculture | B2: Addiction | C2: Agriculture | D2: ='Influence Matrix'!B3 -> -0.08 | E2: Linear | G2: Medium | H2: Low
A3: Addiction_Authoritarianism | B3: Addiction | C3: Authoritarianism | D3: ='Influence Matrix'!B4 -> 0 | G3: High | H3: High
A4: Addiction_Birthrate | B4: Addiction | C4: Birthrate | D4: ='Influence Matrix'!B5 -> -0.16 | E4: Linear | G4: High | H4: Medium
A5: Addiction_Corruption | B5: Addiction | C5: Corruption | D5: ='Influence Matrix'!B6 -> 0 | G5: High | H5: High
A6: Addiction_Cost of Living | B6: Addiction | C6: Cost of Living | D6: ='Influence Matrix'!B7 -> 0.19 | G6: High | H6: Medium
A7: Addiction_Crime | B7: Addiction | C7: Crime | D7: ='Influence Matrix'!B8 -> 0.3 | G7: High | H7: High
A8: Addiction_Deathrate | B8: Addiction | C8: Deathrate | D8: ='Influence Matrix'!B9 -> 0.31 | G8: High | H8: High
A9: Addiction_Discrimination | B9: Addiction | C9: Discrimination | D9: ='Influence Matrix'!B10 -> 0 | G9: Medium | H9: Medium
A10: Addiction_Diversity | B10: Addiction | C10: Diversity | D10: ='Influence Matrix'!B11 -> 0 | G10: High | H10: High
A11: Addiction_Edu: Access | B11: Addiction | C11: Edu: Access | D11: ='Influence Matrix'!B12 -> -0.07 | G11: Medium | H11: Low
A12: Addiction_Edu: Cost | B12: Addiction | C12: Edu: Cost | D12: ='Influence Matrix'!B13 -> 0 | G12: Low | H12: Low
A13: Addiction_Edu: Quality | B13: Addiction | C13: Edu: Quality | D13: ='Influence Matrix'!B14 -> -0.13 | G13: High | H13: Medium
A14: Addiction_Employment | B14: Addiction | C14: Employment | D14: ='Influence Matrix'!B15 -> -0.18 | G14: High | H14: Medium
A15: Addiction_Energy Production | B15: Addiction | C15: Energy Production | D15: ='Influence Matrix'!B16 -> 0 | G15: High | H15: High
A16: Addiction_Equality | B16: Addiction | C16: Equality | D16: ='Influence Matrix'!B17 -> -0.06 | G16: Low | H16: Low
... A35: Addiction_Public Trust | B35: Addiction | C35: Public Trust | D35: ='Influence Matrix'!B36 -> -0.12 | G35: High | H35: Medium
A36: Addiction_Purpose/Meaning | B36: Addiction | C36: Purpose/Meaning | D36: ='Influence Matrix'!B37 -> -0.38 | E36: Power | G36: High | H36: High
A37: Addiction_Religion | B37: Addiction | C37: Religion | D37: ='Influence Matrix'!B38 -> -0.1 | G37: High | H37: Medium
A38: Addiction_Sickness/Disease | B38: Addiction | C38: Sickness/Disease | D38: ='Influence Matrix'!B39 -> 0.31 | G38: High | H38: Medium
A39: Addiction_Taxes | B39: Addiction | C39: Taxes | D39: ='Influence Matrix'!B40 -> 0 | G39: High | H39: High
A40: Addiction_Tech | B40: Addiction | C40: Tech | D40: ='Influence Matrix'!B41 -> 0 | G40: High | H40: High
A41: Addiction_Transportation | B41: Addiction | C41: Transportation | D41: ='Influence Matrix'!B42 -> 0 | G41: High | H41: High
A42: Addiction_Welfare Support | B42: Addiction | C42: Welfare Support | D42: ='Influence Matrix'!B43 -> 0.22 | G42: High | H42: Medium
A43: Agriculture_Addiction | B43: Agriculture | C43: Addiction | D43: ='Influence Matrix'!C2 -> 0.05
A44: Agriculture_Authoritarianism | B44: Agriculture | C44: Authoritarianism | D44: ='Influence Matrix'!C4 -> 0.14
A45: Agriculture_Birthrate | B45: Agriculture | C45: Birthrate | D45: ='Influence Matrix'!C5 -> 0.13
A46: Agriculture_Corruption | B46: Agriculture | C46: Corruption | D46: ='Influence Matrix'!C6 -> 0
A47: Agriculture_Cost of Living | B47: Agriculture | C47: Cost of Living | D47: ='Influence Matrix'!C7 -> -0.16
A48: Agriculture_Crime | B48: Agriculture | C48: Crime | D48: ='Influence Matrix'!C8 -> -0.13
A49: Agriculture_Deathrate | B49: Agriculture | C49: Deathrate | D49: ='Influence Matrix'!C9 -> 0.14
A50: Agriculture_Discrimination | B50: Agriculture | C50: Discrimination | D50: ='Influence Matrix'!C10 -> 0.12
A51: Agriculture_Diversity | B51: Agriculture | C51: Diversity | D51: ='Influence Matrix'!C11 -> 0.11
A52: Agriculture_Edu: Access | B52: Agriculture | C52: Edu: Access | D52: ='Influence Matrix'!C12 -> 0.09
A53: Agriculture_Edu: Cost | B53: Agriculture | C53: Edu: Cost | D53: ='Influence Matrix'!C13 -> -0.08
A54: Agriculture_Edu: Quality | B54: Agriculture | C54: Edu: Quality | D54: ='Influence Matrix'!C14 -> 0.12
A55: Agriculture_Employment | B55: Agriculture | C55: Employment | D55: ='Influence Matrix'!C15 -> 0.24
... A83: Agriculture_Welfare Support | B83: Agriculture | C83: Welfare Support | D83: ='Influence Matrix'!C43 -> 0.18

Sheet Sliders
A1: Addiction
A2: Agriculture
A3: Authoritarianism | F3: Expanded
A4: Birthrate | C4: DO NOT TOUCH: COLUMN A! | F4: Climate Stability | J4: Composites
A5: Corruption | F5: CO2 Emmisions
A6: Cost of Living | F6: Creativity
A7: Crime | F7: LGBTQIA+
A8: Deathrate | F8: Migration
A9: Discrimination | F9: Resilience
A10: Diversity | F10: Sexual Freedom
A11: Edu: Access | F11: Stigma
A12: Edu: Cost | F12: Surveillance
A13: Edu: Quality | F13: Wage Gap
A14: Employment | F14: Sex Ratio
A15: Energy Production | F15: Patriarchy
A16: Equality | F16: Emigration
A17: Family Values
A18: Freedom of Speech
A19: Gun Rights
A20: HC Access | F20: Healthcare
A21: HC Cost | F21: Healthcare Access
A22: HC Quality | F22: Healthcare Cost
A23: Homelessness | F23: Healthcare Quality
A24: Immigration
A25: Infrastructure
A26: Innovation
A27: Law Enforcement
A28: Liberty
A29: Market Freedom
A30: Mental Health
A31: Military
A32: Minimum Wage
A33: Pollution
A34: Poverty
A35: Public Trust
A36: Purpose/Meaning
A37: Religion | C37: Religion needs to be changed to "Theism" or "Spirituality"
A38: Sickness/Disease
A39: Taxes
A40: Tech
...

Sheet Indicators
B3: Approved | I3: Ideas
B4: Quality of Living | I4: Capitalism
B5: Social Tension | I5: Nihilism
B6: Societal Cohesion | I6: War
I7: Anarchy
I8: Utopia
I9: Civil War
I10: Civil Unrest

Sheet Enums
A1: Shapes
A2: Linear
A3: Tanh
A4: Sigmoid
A5: ReLU
A6: Power
