Workbook

Sheet esp32 (v2)
A1: ESP Pin | C1: Pinout / Connections
A2: 3V3 | C2: 3.3V Output
A3: 3V3_EN | C3: 3.3V Enable (not used)
A4: EXIO1 | C4: Rotary Encoder - SW
A5: EXIO2 | C5: TB6612 [ 2] - BIN1 (Slider 2 +)
A6: EXIO3 | C6: TB6612 [ 2] - BIN2 (Slider 2 -)
A7: EXIO4 | C7: TB6612 [3] - AIN1 (Slider 1 +)
A8: EXIO5 | C8: TB6612 [3] - AIN2 (Slider 1 -)
A9: EXIO6 | C9: TB6612 [2] - AIN1 (Slider 3 +)
A10: EXIO7 | C10: TB6612 Standby (Shared pin)
A11: GND | C11: Ground
A12: GND | C12: Ground
... A18: GND | C18: Ground
A19: GPIO0 | B19: adc | C19: Slider Pot 1
A20: GPIO1 | B20: adc | C20: Slider Pot 2
A21: GPIO14 | C21: TB6612 [ 1] - PWMA
A22: GPIO15 | B22: strap | C22: TB6612 [2] - AIN2 (Slider 3 -)
A23: GPIO16 (TXD) | C23: TB6612 [2] - PWMA
A24: GPIO17 (RXD) | C24: TB6612 [2] - PWMB
A25: GPIO18 | C25: Rotary Encoder - CLK
A26: GPIO19 | C26: Rotary Encoder - DT
A27: GPIO2 | B27: adc | C27: Slider Pot 3
A28: GPIO20 | C28: PCA9548A - SDA
A29: GPIO21 | C29: PCA9548A - SCL
A30: GPIO22 | C30: TB6612 [3] - PWMA
A31: GPIO23 | C31: TB6612 [ 1] - PWMB
A32: GPIO3 | B32: adc | C32: Slider Pot 4
A33: GPIO4 | C33: TB6612 [ 1] - BIN1 (Slider 4 +)
A34: GPIO5 | B34: adc | C34: Button Ladder
A35: GPIO6 | B35: adc | C35: Slider Pot 5
A36: GPIO7 | C36: TB6612 [ 1] - BIN2 (Slider 4 -)
A37: GPIO8 | B37: strap | C37: TB6612 [ 1 ]- AIN1 (Slider 5 +)
A38: GPIO9 | B38: strap | C38: TB6612 [ 1] - AIN2 (Slider 5 -)
A39: RUN | C39: -
A40: Vbus | C40: USB 5V Input
A41: Vsys | C41: System Power (5v input)

Sheet TB6612FNG
B5: 5V | C5: VM | D5: 1 | E5: PWMA | F5: ='esp32 (v2)'!A21 -> GPIO14
B6: 3.3V | C6: VCC | E6: AI2 | F6: ='esp32 (v2)'!A24 -> GPIO17 (RXD)
B7: ='esp32 (v2)'!A12 -> GND | C7: GND | E7: AI1 | F7: ='esp32 (v2)'!A23 -> GPIO16 (TXD)
B8: Slider 5 + | C8: A01 | E8: STBY | F8: EXIO07
B9: Slider 5 - | C9: A02 | E9: BI1 | F9: ='esp32 (v2)'!A33 -> GPIO4
B10: Slider 4 - | C10: B02 | E10: BI2 | F10: ='esp32 (v2)'!A36 -> GPIO7
B11: Slider 4 + | C11: B01 | E11: PWMB | F11: ='esp32 (v2)'!A22 -> GPIO15
B12: ='esp32 (v2)'!A13 -> GND | C12: GND | E12: GND | F12: GND
B14: =B5 -> 5V | C14: VM | D14: 2 | E14: PWMA | F14: ='esp32 (v2)'!A37 -> GPIO8
B15: 3V3 | C15: VCC | E15: AI2 | F15: ='esp32 (v2)'!A31 -> GPIO23
B16: ='esp32 (v2)'!A13 -> GND | C16: GND | E16: AI1 | F16: ='esp32 (v2)'!A9 -> EXIO6
B17: Slider 3 + | C17: A01 | E17: STBY | F17: ='esp32 (v2)'!A10 -> EXIO7
B18: Slider 3 - | C18: A02 | E18: BI1 | F18: ='esp32 (v2)'!A5 -> EXIO2
B19: Slider 2 - | C19: B02 | E19: BI2 | F19: ='esp32 (v2)'!A6 -> EXIO3
B20: Slider 2 + | C20: B01 | E20: PWMB | F20: ='esp32 (v2)'!A38 -> GPIO9
B21: ='esp32 (v2)'!A13 -> GND | C21: GND | E21: GND | F21: ='esp32 (v2)'!A13 -> GND
B23: =B5 -> 5V | C23: VM | D23: 3 | E23: PWMA | F23: ='esp32 (v2)'!A30 -> GPIO22
B24: 3V3 | C24: VCC | E24: AI2 | F24: ='esp32 (v2)'!A8 -> EXIO5
B25: ='esp32 (v2)'!A13 -> GND | C25: GND | E25: AI1 | F25: ='esp32 (v2)'!A7 -> EXIO4
B26: Slider 1+ | C26: A01 | E26: STBY | F26: ='esp32 (v2)'!A10 -> EXIO7
B27: Slider 1 - | C27: A02 | E27: BI1 | F27: x
B28: x | C28: B02 | E28: BI2 | F28: x
B29: x | C29: B01 | E29: PWMB | F29: x
B30: ='esp32 (v2)'!A12 -> GND | C30: GND | E30: GND | F30: ='esp32 (v2)'!A13 -> GND

Sheet pca9548a
A3: 3.3V | B3: VIN | D3: SC7 | E3: X
A4: GND | B4: GND | D4: SD7 | E4: X
A5: ='esp32 (v2)'!A28 -> GPIO20 | B5: SDA | D5: SC6 | E5: X
A6: ='esp32 (v2)'!A29 -> GPIO21 | B6: SCL | D6: SD6 | E6: X
A7: 3v3 | B7: RST | D7: SC5 | E7: X
A8: GND | B8: A0 | D8: SD5 | E8: X
A9: GND | B9: A1 | D9: SC4 | E9: OLED5
A10: GND | B10: A2 | D10: SD4 | E10: OLED5
A11: OLED1 | B11: SD0 | D11: SC3 | E11: OLED4
A12: OLED1 | B12: SC0 | D12: SD3 | E12: OLED4
A13: OLED2 | B13: SD1 | D13: SC2 | E13: OLED3
A14: OLED2 | B14: SC1 | D14: SD2 | E14: OLED3
B31: Connect RESET to 3.3V through a 10k pull-up resistor and a small capacitor (e.g., 0.1 µF) from RESET to GND.

Sheet WAVESHARE ESP32 C6 Pico PINOUT
A1: WAVESHARE ESP32 CD PICO
A2: PIN | B2: PWM | C2: BUILT-IN | D2: ADC | E2: UART | F2: STRAPPING
A3: Vbus
A4: Vsys
A5: GND
A6: 3V3_EN
A7: 3V3
A8: GPIO0 | B8: PWM | D8: ADC1_CH0 | G8: slider pot 1
A9: GPIO1 | B9: PWM | D9: ADC1_CH1 | G9: slider pot 2
A10: GND
A11: GPIO2 | B11: PWM | D11: ADC1_CH2 | G11: slider pot 3
A12: GPIO3 | B12: PWM | D12: ADC1_CH3 | G12: slider pot 4
A13: RUN
A14: EXIO1 | B14: PWM
A15: GND
A16: GPIO23 | B16: PWM
A17: GPIO22 | B17: PWM
A18: EXIO2 | B18: PWM
A19: EXIO3 | B19: PWM
A20: GND
A21: EXIO4 | B21: PWM
A22: EXIO5 | B22: PWM
A23: GPIO16 (TXD) | B23: PWM | E23: U0TXD
A24: GPIO17 (RXD) | B24: PWM | E24: U0RXD
A25: GND
A26: GPIO4 | B26: PWM | D26: ADC1_CH4 | F26: SDIO
A27: GPIO5 | B27: PWM | D27: ADC1_CH5 | F27: SDIO | G27: button ladder
A28: GPIO6 | B28: PWM | D28: ADC1_CH6 | G28: slider pot 5
A29: GPIO7 | B29: PWM
A30: GND
A31: GPIO14 | B31: PWM
A32: GPIO15 | B32: PWM | F32: JTAG
A33: GPIO8 | B33: PWM | C33: RGB LED | F33: ROM
A34: GPIO9 | B34: PWM | F34: BOOT
A35: GND
A36: GPIO18 | B36: PWM
A37: GPIO19 | B37: PWM
A38: GPIO20 | B38: PWM
A39: GPIO21 | B39: PWM
A40: GND
...
