Workbook

Sheet Waveshare ESP32-C6-Pico
A1: ESP Pin | B1: *Pin | C1: Pinout / Connections | D1: Color | E1: Pass/Fail | F1: Notes
A2: 3V3 | C2: 3.3V Output
A3: 3V3_EN | C3: 3.3V Enable (not used)
A4: EXIO1 | C4: Rotary Encoder - SW
A5: EXIO2 | C5: TB6612 [ 2] - BIN1 (Slider 2 +)
A6: EXIO3 | C6: TB6612 [ 2] - BIN2 (Slider 2 -)
A7: EXIO4 | C7: TB6612 [3] - AIN1 (Slider 1 +)
A8: EXIO5 | C8: TB6612 [3] - AIN2 (Slider 1 -)
A9: EXIO6 | C9: TB6612 [2] - AIN1 (Slider 3 +)
A10: EXIO7 | C10: Killswitch + Latching Isolation
A11: GND | C11: Common Ground
A12: GND | C12: Common Ground
A13: GND | C13: Common Ground
... A18: GND | C18: Common Ground
A19: GPIO0 | B19: adc | C19: Slider Pot 1
A20: GPIO1 | B20: adc | C20: Slider Pot 2
A21: GPIO14 | C21: TB6612 [ 1] - PWMA
A22: GPIO15 | B22: strap | C22: TB6612 [1] - AIN2 (Slider 5 -)
A23: GPIO16 (TXD) | C23: TB6612 [2] - PWMA
A24: GPIO17 (RXD) | C24: TB6612 [1] - PWMB
A25: GPIO18 | C25: Rotary Encoder - CLK
A26: GPIO19 | C26: Rotary Encoder - DT
A27: GPIO2 | B27: adc | C27: Slider Pot 3
A28: GPIO20 | C28: PCA9548A - SDA
A29: GPIO21 | C29: PCA9548A - SCL
A30: GPIO22 | C30: TB6612 [3] - PWMA
A31: GPIO23 | C31: TB6612 [ 2] - PWMB
A32: GPIO3 | B32: adc | C32: Slider Pot 4
A33: GPIO4 | C33: TB6612 [ 1] - BIN1 (Slider 4 +)
A34: GPIO5 | B34: adc | C34: Button Ladder
A35: GPIO6 | B35: adc | C35: Slider Pot 5
A36: GPIO7 | C36: TB6612 [ 1] - BIN2 (Slider 4 -)
A37: GPIO8 | B37: strap | C37: TB6612 [ 1 ]- AIN1 (Slider 5 +)
A38: GPIO9 | B38: strap | C38: TB6612 [ 2] - AIN2 (Slider 3 -)
A39: RUN | C39: -
A40: Vbus | C40: USB 5V Input
A41: Vsys | C41: System Power (5v input)

Sheet TB6612FNG
A1: Driver 1
A2: VM | B2: 5V
A3: VCC | B3: 3.3V
A4: GND | B4: ='Waveshare ESP32-C6-Pico'!A12 -> GND
A5: A01 | B5: Slider 5 +
A6: A02 | B6: Slider 5 -
A7: B02 | B7: Slider 4 -
A8: B01 | B8: Slider 4 +
A9: GND | B9: ='Waveshare ESP32-C6-Pico'!A13 -> GND
A10: PWMA | B10: ='Waveshare ESP32-C6-Pico'!A21 -> GPIO14
A11: AI2 | B11: ='Waveshare ESP32-C6-Pico'!A22 -> GPIO15
A12: AI1 | B12: ='Waveshare ESP32-C6-Pico'!A37 -> GPIO8
A13: STBY | B13: EXIO07
A14: BI1 | B14: ='Waveshare ESP32-C6-Pico'!A33 -> GPIO4
A15: BI2 | B15: ='Waveshare ESP32-C6-Pico'!A36 -> GPIO7
A16: PWMB | B16: ='Waveshare ESP32-C6-Pico'!A24 -> GPIO17 (RXD)
A17: GND | B17: GND
A18: Driver 2
A19: VM | B19: =B2 -> 5V
A20: VCC | B20: 3V3
A21: GND | B21: ='Waveshare ESP32-C6-Pico'!A13 -> GND
A22: A01 | B22: Slider 3 +
A23: A02 | B23: Slider 3 -
A24: B02 | B24: Slider 2 -
A25: B01 | B25: Slider 2 +
A26: GND | B26: ='Waveshare ESP32-C6-Pico'!A13 -> GND
A27: PWMA | B27: ='Waveshare ESP32-C6-Pico'!A23 -> GPIO16 (TXD)
A28: AI2 | B28: ='Waveshare ESP32-C6-Pico'!A38 -> GPIO9
A29: AI1 | B29: ='Waveshare ESP32-C6-Pico'!A9 -> EXIO6
A30: STBY | B30: ='Waveshare ESP32-C6-Pico'!A10 -> EXIO7
A31: BI1 | B31: ='Waveshare ESP32-C6-Pico'!A5 -> EXIO2
A32: BI2 | B32: ='Waveshare ESP32-C6-Pico'!A6 -> EXIO3
A33: PWMB | B33: ='Waveshare ESP32-C6-Pico'!A24 -> GPIO17 (RXD)
A34: GND | B34: ='Waveshare ESP32-C6-Pico'!A13 -> GND
A35: Driver 3
A36: PWMA | B36: ='Waveshare ESP32-C6-Pico'!A30 -> GPIO22
A37: AI2 | B37: ='Waveshare ESP32-C6-Pico'!A8 -> EXIO5
A38: AI1 | B38: ='Waveshare ESP32-C6-Pico'!A7 -> EXIO4
A39: STBY | B39: ='Waveshare ESP32-C6-Pico'!A10 -> EXIO7
A40: BI1 | B40: x
...

Sheet pca9548a
A3: 3.3V | B3: VIN | D3: SC7 | E3: X
A4: GND | B4: GND | D4: SD7 | E4: X
A5: ='Waveshare ESP32-C6-Pico'!A28 -> GPIO20 | B5: SDA | D5: SC6 | E5: X
A6: ='Waveshare ESP32-C6-Pico'!A29 -> GPIO21 | B6: SCL | D6: SD6 | E6: X
A7: 3v3 | B7: RST | D7: SC5 | E7: X
A8: GND | B8: A0 | D8: SD5 | E8: X
A9: GND | B9: A1 | D9: SC4 | E9: OLED5
A10: GND | B10: A2 | D10: SD4 | E10: OLED5
A11: OLED1 | B11: SD0 | D11: SC3 | E11: OLED4
A12: OLED1 | B12: SC0 | D12: SD3 | E12: OLED4
A13: OLED2 | B13: SD1 | D13: SC2 | E13: OLED3
A14: OLED2 | B14: SC1 | D14: SD2 | E14: OLED3
B31: Connect RESET to 3.3V through a 10k pull-up resistor and a small capacitor (e.g., 0.1 µF) from RESET to GND.

Sheet KY-040
C3: KY-040 Pin | D3: ESP32 Pin
C4: CLK | D4: ='Waveshare ESP32-C6-Pico'!A25 -> GPIO18
C5: DT | D5: ='Waveshare ESP32-C6-Pico'!A26 -> GPIO19
C6: SW | D6: ='Waveshare ESP32-C6-Pico'!C4 -> Rotary Encoder - SW
C7: VCC+ | D7: 3V3 (Main 3V3 rail, not mcu)
C8: GND | D8: GND (Common GND)
